Workbook

Sheet Version-Level Changes
B2: v4: Yellow tabs represent changes listed below while the light orange tabs mean that changes may come or TBD
B3: - In the "INT Web" tab, maintaining the 2025-26 Start of Season pricing with the following exceptions:
C4: => Due to FX devaluation from inflation risk across many seasons, changing NBA.com currency for Argentina to USD from ARS - pricing now matches 2025-26 in-app and CED pricing (reported in USD)
C5: => To maximize revenue, increasing only League Pass Premium pricing (Monthly and SL / Annual) in Australia
C6: => Due to FX devaluation from inflation risk, increasing pricing for all packages in Nigeria by ~4% YoY
C7: => Due to FX devaluation from inflation risk, increasing pricing for all packages in Romania by ~13% YoY
C8: => Due to FX devaluation from inflation risk, increasing pricing for all packages in Turkey by ~45% YoY
B9: - In the "Student Plan Web" tab, added India pricing as it's being sold in a new market for Student Plans in the 2026-27 season
B10: - In the "Apple" tab, increasing prices across subscription and/or transactional packages to match the changes seen in the "INT Web" tab for Australia, Nigeria, Romania, and Turkey
C11: => Note: Price increases for existing in-app subscribers will occur around November. Thus, only new paying sign-ups will purchase at the higher prices.
B12: - In the "Google" tab, increased prices across subscription and/or transactional packages to match the changes seen in the "INT Web" tab for Australia, Cameroon, Cote D'Ivoire, Nigeria, Romania, Senegal, and Turkey
C13: => Note: Price increases for existing in-app subscribers will occur around November. Thus, only new paying sign-ups will purchase at the higher prices.
B14: - In the "AMZN Fire TV" tab, increasing only League Pass Premium pricing (Monthly and Annual) in Australia
C15: => Note: Price increases for existing in-app subscribers will occur around November. Thus, only new paying sign-ups will purchase at the higher prices.
B16: - In the "Samsung" tab, increasing prices across Australia (LPP Only), Nigeria, and Turkey
C17: => Note: Price increases for existing in-app subscribers will occur around November. Thus, only new paying sign-ups will purchase at the higher prices.
B18: - In the "Country-Level Tactics" tab, added country-level tactics across pricing, offers, and BFCM for the Monetization team's reference
B19: - In the "Addt'l Payment Methods" tab, Kenny made the following updates ahead of the 2026-27 season: Added Klarna Pay Now in Finland and United Kingdom; Venmo in the U.S.
B20: - In the "Intro Offer Details" tab, updated introductory pricing to 30% off (from 35% off) for Annual (Pay Up Front) subscriptions across both the Apple and Google platforms
B21: - In the "Post-AR Web Cancel Deflection" tab, (i) identified the global SL save offer turn off date as 8/27/26, and (ii), in select markets only, adjusted monthly save offers from pause to 100% off next month
B22: - In the "Cancel Deflection - Apple" tab, updated certain markets (e.g., United States) to remove save offers (feasibility of doing this by market is an open question with Chelsea and Apple)
B23: - In the "Winback - Apple" tab, turned back on offers from 10.01 to 10.15; offers are 15% off all SKUs for select markets only (will remain off in others)
B24: - In the "Winback - Google" tab, turned back on offers from 10.01 to 10.15; offers are 15% off all SKUs for select markets only (will remain off in others)
B26: v5: Yellow tabs represent changes listed below while the light orange tabs mean that changes may come or TBD
B27: v6 will include the TBU changes that are highlighted in light orange above
B28: - In all Apple-related tabs, added the three-digit country code
B30: v6
B31: - In all tabs that showcase country x region mapping, updated French Guiana, Guadeloupe, Martinique, Mayotte, and Reunion to Africa (from what originally was LatAm or Africa)
... B41: '- Accurately depicted Bulgaria's currency from USD to EUR - no changes to pricing in absolute terms, just the currency change

Sheet SKU & Platform Availability ->

Sheet DOM
B2: Country | C2: Region | D2: BLPEUS | E2: BLPEUSMONTHLY | F2: BLPPUS | G2: BLPPUSMONTHLY | H2: BTCUS | I2: BTCUSMONTHLY | J2: BLPTV | K2: BLPTVMONTHLY | L2: GSINGLEGAMEUS | M2: GSINGLEGAMEUSA | N2: GSINGLEGAMEUSB | O2: GSINGLEGAMEUSC | P2: BLPAUDIO
B3: United States | C3: Domestic | D3: Web & IAP | E3: Web & IAP | F3: Web & IAP | G3: Web & IAP | H3: Web | I3: Web | J3: Web | K3: Web | L3: IAP | M3: IAP | N3: IAP | O3: IAP | P3: Web
B4: Guam | C4: Domestic | D4: =+D3 -> Web & IAP | E4: =+E3 -> Web & IAP | F4: =+F3 -> Web & IAP | G4: =+G3 -> Web & IAP | H4: =+H3 -> Web | I4: =+I3 -> Web | J4: =+J3 -> Web | K4: =+K3 -> Web | ... P4: =+P3 -> Web
B5: Puerto Rico | C5: Domestic | D5: =+D4 -> Web & IAP | E5: =+E4 -> Web & IAP | F5: =+F4 -> Web & IAP | G5: =+G4 -> Web & IAP | H5: =+H4 -> Web | I5: =+I4 -> Web | J5: =+J4 -> Web | K5: =+K4 -> Web | ... P5: =+P4 -> Web
B6: US Virgin Islands | C6: Domestic | D6: =+D5 -> Web & IAP | E6: =+E5 -> Web & IAP | F6: =+F5 -> Web & IAP | G6: =+G5 -> Web & IAP | H6: =+H5 -> Web | I6: =+I5 -> Web | J6: =+J5 -> Web | K6: =+K5 -> Web | ... P6: =+P5 -> Web
B7: US Minor Outlying Islands | C7: Domestic | D7: =+D6 -> Web & IAP | E7: =+E6 -> Web & IAP | F7: =+F6 -> Web & IAP | G7: =+G6 -> Web & IAP | H7: =+H6 -> Web | I7: =+I6 -> Web | J7: =+J6 -> Web | K7: =+K6 -> Web | ... P7: =+P6 -> Web

Sheet INT
B2: Country | C2: Region | D2: BLPE | E2: BLPEMONTHLY | F2: BLPP | G2: BLPPMONTHLY | H2: BTC | I2: BTCMONTHLY | J2: GSINGLEGAME | K2: GSINGLEGAMEA | L2: GSINGLEGAMEB | M2: GSINGLEGAMEC | N2: BLPE1C | O2: BLPE2C | P2: BLPE3C | Q2: Apple | R2: Google
B3: Afghanistan | C3: =+VLOOKUP($B3,'[2]Pricing Scenario - Maintain'!$B$4:$AM$238,2,FALSE) -> Asia | D3: Web & IAP | E3: Web & IAP | F3: Web & IAP | G3: Web & IAP | H3: Web | I3: Web | J3: IAP | K3: IAP | L3: IAP | M3: IAP | N3: Web | O3: Web | P3: Web | Q3: =+IFERROR(VLOOKUP(B3,[2]Apple!$B$3:$C$173,2,FALSE),"") -> AF | R3: =+IFERROR(VLOOKUP(B3,[2]Google!$B$3:$C$99,2,FALSE),"")
B4: Aland Islands | C4: =+VLOOKUP($B4,'[2]Pricing Scenario - Maintain'!$B$4:$AM$238,2,FALSE) -> Europe | D4: Web / IAP | E4: Web / IAP | F4: Web / IAP | G4: Web / IAP | H4: Web | I4: Web | J4: IAP | K4: IAP | L4: IAP | M4: IAP | N4: Web | O4: Web | P4: Web | Q4: =+IFERROR(VLOOKUP(B4,[2]Apple!$B$3:$C$173,2,FALSE),"") | R4: =+IFERROR(VLOOKUP(B4,[2]Google!$B$3:$C$99,2,FALSE),"")
B5: Albania | C5: =+VLOOKUP($B5,'[2]Pricing Scenario - Maintain'!$B$4:$AM$238,2,FALSE) -> Europe | D5: Web & IAP | E5: Web & IAP | F5: Web & IAP | G5: Web & IAP | H5: Web | I5: Web | J5: IAP | K5: IAP | L5: IAP | M5: IAP | N5: Web | O5: Web | P5: Web | Q5: =+IFERROR(VLOOKUP(B5,[2]Apple!$B$3:$C$173,2,FALSE),"") -> AL | R5: =+IFERROR(VLOOKUP(B5,[2]Google!$B$3:$C$99,2,FALSE),"") -> AL
B6: Algeria | C6: =+VLOOKUP($B6,'[2]Pricing Scenario - Maintain'!$B$4:$AM$238,2,FALSE) -> Africa | D6: Web & IAP | E6: Web & IAP | F6: Web & IAP | G6: Web & IAP | H6: Web | I6: Web | J6: IAP | K6: IAP | L6: IAP | M6: IAP | N6: Web | O6: Web | P6: Web | Q6: =+IFERROR(VLOOKUP(B6,[2]Apple!$B$3:$C$173,2,FALSE),"") -> DZ | R6: =+IFERROR(VLOOKUP(B6,[2]Google!$B$3:$C$99,2,FALSE),"") -> DZ
B7: American Samoa | C7: =+VLOOKUP($B7,'[2]Pricing Scenario - Maintain'!$B$4:$AM$238,2,FALSE) -> Asia | D7: Web / IAP | E7: Web / IAP | F7: Web / IAP | G7: Web / IAP | H7: Web | I7: Web | J7: IAP | K7: IAP | L7: IAP | M7: IAP | N7: Web | O7: Web | P7: Web | Q7: =+IFERROR(VLOOKUP(B7,[2]Apple!$B$3:$C$173,2,FALSE),"") | R7: =+IFERROR(VLOOKUP(B7,[2]Google!$B$3:$C$99,2,FALSE),"")
B8: Andorra | C8: =+VLOOKUP($B8,'[2]Pricing Scenario - Maintain'!$B$4:$AM$238,2,FALSE) -> Europe | D8: Web / IAP | E8: Web / IAP | F8: Web / IAP | G8: Web / IAP | H8: Web | I8: Web | J8: IAP | K8: IAP | L8: IAP | M8: IAP | N8: Web | O8: Web | P8: Web | Q8: =+IFERROR(VLOOKUP(B8,[2]Apple!$B$3:$C$173,2,FALSE),"") | R8: =+IFERROR(VLOOKUP(B8,[2]Google!$B$3:$C$99,2,FALSE),"")
B9: Angola | C9: =+VLOOKUP($B9,'[2]Pricing Scenario - Maintain'!$B$4:$AM$238,2,FALSE) -> Africa | D9: Web & IAP | E9: Web & IAP | F9: Web & IAP | G9: Web & IAP | H9: Web | I9: Web | J9: IAP | K9: IAP | L9: IAP | M9: IAP | N9: Web | O9: Web | P9: Web | Q9: =+IFERROR(VLOOKUP(B9,[2]Apple!$B$3:$C$173,2,FALSE),"") -> AO | R9: =+IFERROR(VLOOKUP(B9,[2]Google!$B$3:$C$99,2,FALSE),"") -> AO
B10: Anguilla | C10: =+VLOOKUP($B10,'[2]Pricing Scenario - Maintain'!$B$4:$AM$238,2,FALSE) -> Latin America | D10: Web & IAP | E10: Web & IAP | F10: Web & IAP | G10: Web & IAP | H10: Web | I10: Web | J10: IAP | K10: IAP | L10: IAP | M10: IAP | N10: Web | O10: Web | P10: Web | Q10: =+IFERROR(VLOOKUP(B10,[2]Apple!$B$3:$C$173,2,FALSE),"") -> AI | R10: =+IFERROR(VLOOKUP(B10,[2]Google!$B$3:$C$99,2,FALSE),"")
B11: Antarctica | C11: =+VLOOKUP($B11,'[2]Pricing Scenario - Maintain'!$B$4:$AM$238,2,FALSE) -> Europe | D11: Web / IAP | E11: Web / IAP | F11: Web / IAP | G11: Web / IAP | H11: Web | I11: Web | J11: IAP | K11: IAP | L11: IAP | M11: IAP | N11: Web | O11: Web | P11: Web | Q11: =+IFERROR(VLOOKUP(B11,[2]Apple!$B$3:$C$173,2,FALSE),"") | R11: =+IFERROR(VLOOKUP(B11,[2]Google!$B$3:$C$99,2,FALSE),"")
B12: Antigua And Barbuda | C12: =+VLOOKUP($B12,'[2]Pricing Scenario - Maintain'!$B$4:$AM$238,2,FALSE) -> Latin America | D12: Web & IAP | E12: Web & IAP | F12: Web & IAP | G12: Web & IAP | H12: Web | I12: Web | J12: IAP | K12: IAP | L12: IAP | M12: IAP | N12: Web | O12: Web | P12: Web | Q12: =+IFERROR(VLOOKUP(B12,[2]Apple!$B$3:$C$173,2,FALSE),"") -> AG | R12: =+IFERROR(VLOOKUP(B12,[2]Google!$B$3:$C$99,2,FALSE),"") -> AG
B13: Argentina | C13: =+VLOOKUP($B13,'[2]Pricing Scenario - Maintain'!$B$4:$AM$238,2,FALSE) -> Latin America | D13: Web & IAP | E13: Web & IAP | F13: Web & IAP | G13: Web & IAP | H13: Web | I13: Web | J13: IAP | K13: IAP | L13: IAP | M13: IAP | N13: Web | O13: Web | P13: Web | Q13: =+IFERROR(VLOOKUP(B13,[2]Apple!$B$3:$C$173,2,FALSE),"") -> AR | R13: =+IFERROR(VLOOKUP(B13,[2]Google!$B$3:$C$99,2,FALSE),"") -> AR
B14: Armenia | C14: =+VLOOKUP($B14,'[2]Pricing Scenario - Maintain'!$B$4:$AM$238,2,FALSE) -> Middle East | D14: Web & IAP | E14: Web & IAP | F14: Web & IAP | G14: Web & IAP | H14: Web | I14: Web | J14: IAP | K14: IAP | L14: IAP | M14: IAP | N14: Web | O14: Web | P14: Web | Q14: =+IFERROR(VLOOKUP(B14,[2]Apple!$B$3:$C$173,2,FALSE),"") -> AM | R14: =+IFERROR(VLOOKUP(B14,[2]Google!$B$3:$C$99,2,FALSE),"") -> AM
... B22: Barbados | C22: =+VLOOKUP($B22,'[2]Pricing Scenario - Maintain'!$B$4:$AM$238,2,FALSE) -> Latin America | D22: Web & IAP | E22: Web & IAP | F22: Web & IAP | G22: Web & IAP | H22: Web | I22: Web | J22: IAP | K22: IAP | L22: IAP | M22: IAP | N22: Web | O22: Web | P22: Web | Q22: =+IFERROR(VLOOKUP(B22,[2]Apple!$B$3:$C$173,2,FALSE),"") -> BB | R22: =+IFERROR(VLOOKUP(B22,[2]Google!$B$3:$C$99,2,FALSE),"")
B23: Belarus | C23: =+VLOOKUP($B23,'[2]Pricing Scenario - Maintain'!$B$4:$AM$238,2,FALSE) -> Europe | Q23: =+IFERROR(VLOOKUP(B23,[2]Apple!$B$3:$C$173,2,FALSE),"") -> BY | R23: =+IFERROR(VLOOKUP(B23,[2]Google!$B$3:$C$99,2,FALSE),"") -> BY
B24: Belgium | C24: =+VLOOKUP($B24,'[2]Pricing Scenario - Maintain'!$B$4:$AM$238,2,FALSE) -> Europe | D24: Web & IAP | E24: Web & IAP | F24: Web & IAP | G24: Web & IAP | H24: Web | I24: Web | J24: IAP | K24: IAP | L24: IAP | M24: IAP | N24: Web | O24: Web | P24: Web | Q24: =+IFERROR(VLOOKUP(B24,[2]Apple!$B$3:$C$173,2,FALSE),"") -> BE | R24: =+IFERROR(VLOOKUP(B24,[2]Google!$B$3:$C$99,2,FALSE),"") -> BE
B25: Belize | C25: =+VLOOKUP($B25,'[2]Pricing Scenario - Maintain'!$B$4:$AM$238,2,FALSE) -> Latin America | D25: Web & IAP | E25: Web & IAP | F25: Web & IAP | G25: Web & IAP | H25: Web | I25: Web | J25: IAP | K25: IAP | L25: IAP | M25: IAP | N25: Web | O25: Web | P25: Web | Q25: =+IFERROR(VLOOKUP(B25,[2]Apple!$B$3:$C$173,2,FALSE),"") -> BZ | R25: =+IFERROR(VLOOKUP(B25,[2]Google!$B$3:$C$99,2,FALSE),"") -> BZ
B26: Benin | C26: =+VLOOKUP($B26,'[2]Pricing Scenario - Maintain'!$B$4:$AM$238,2,FALSE) -> Africa | D26: Web & IAP | E26: Web & IAP | F26: Web & IAP | G26: Web & IAP | H26: Web | I26: Web | J26: IAP | K26: IAP | L26: IAP | M26: IAP | N26: Web | O26: Web | P26: Web | Q26: =+IFERROR(VLOOKUP(B26,[2]Apple!$B$3:$C$173,2,FALSE),"") -> BJ | R26: =+IFERROR(VLOOKUP(B26,[2]Google!$B$3:$C$99,2,FALSE),"") -> BJ
B27: Bermuda | C27: Latin America | D27: Web & IAP | E27: Web & IAP | F27: Web & IAP | G27: Web & IAP | H27: Web | I27: Web | J27: IAP | K27: IAP | L27: IAP | M27: IAP | N27: Web | O27: Web | P27: Web | Q27: =+IFERROR(VLOOKUP(B27,[2]Apple!$B$3:$C$173,2,FALSE),"") -> BM | R27: =+IFERROR(VLOOKUP(B27,[2]Google!$B$3:$C$99,2,FALSE),"") -> BM
B28: Bhutan | C28: =+VLOOKUP($B28,'[2]Pricing Scenario - Maintain'!$B$4:$AM$238,2,FALSE) -> Asia | D28: Web & IAP | E28: Web & IAP | F28: Web & IAP | G28: Web & IAP | H28: Web | I28: Web | J28: IAP | K28: IAP | L28: IAP | M28: IAP | N28: Web | O28: Web | P28: Web | Q28: =+IFERROR(VLOOKUP(B28,[2]Apple!$B$3:$C$173,2,FALSE),"") -> BT | R28: =+IFERROR(VLOOKUP(B28,[2]Google!$B$3:$C$99,2,FALSE),"")
B29: Bolivia | C29: Latin America | D29: Web & IAP | E29: Web & IAP | F29: Web & IAP | G29: Web & IAP | H29: Web | I29: Web | J29: IAP | K29: IAP | L29: IAP | M29: IAP | N29: Web | O29: Web | P29: Web | Q29: =+IFERROR(VLOOKUP(B29,[2]Apple!$B$3:$C$173,2,FALSE),"") -> BO | R29: =+IFERROR(VLOOKUP(B29,[2]Google!$B$3:$C$99,2,FALSE),"") -> BO
B30: Bonaire, St. Eustatius, & Saba | C30: Europe | D30: Web / IAP | E30: Web / IAP | F30: Web / IAP | G30: Web / IAP | H30: Web | I30: Web | J30: IAP | K30: IAP | L30: IAP | M30: IAP | N30: Web | O30: Web | P30: Web | Q30: =+IFERROR(VLOOKUP(B30,[2]Apple!$B$3:$C$173,2,FALSE),"") | R30: =+IFERROR(VLOOKUP(B30,[2]Google!$B$3:$C$99,2,FALSE),"")
B31: Bosnia And Herzegovina | C31: =+VLOOKUP($B31,'[2]Pricing Scenario - Maintain'!$B$4:$AM$238,2,FALSE) -> Europe | D31: Web & IAP | E31: Web & IAP | F31: Web & IAP | G31: Web & IAP | H31: Web | I31: Web | J31: IAP | K31: IAP | L31: IAP | M31: IAP | N31: Web | O31: Web | P31: Web | Q31: =+IFERROR(VLOOKUP(B31,[2]Apple!$B$3:$C$173,2,FALSE),"") -> BA | R31: =+IFERROR(VLOOKUP(B31,[2]Google!$B$3:$C$99,2,FALSE),"") -> BA
B32: Botswana | C32: =+VLOOKUP($B32,'[2]Pricing Scenario - Maintain'!$B$4:$AM$238,2,FALSE) -> Africa | D32: Web & IAP | E32: Web & IAP | F32: Web & IAP | G32: Web & IAP | H32: Web | I32: Web | J32: IAP | K32: IAP | L32: IAP | M32: IAP | N32: Web | O32: Web | P32: Web | Q32: =+IFERROR(VLOOKUP(B32,[2]Apple!$B$3:$C$173,2,FALSE),"") -> BW | R32: =+IFERROR(VLOOKUP(B32,[2]Google!$B$3:$C$99,2,FALSE),"") -> BW
B33: Bouvet Island | C33: =+VLOOKUP($B33,'[2]Pricing Scenario - Maintain'!$B$4:$AM$238,2,FALSE) -> Europe | D33: Web / IAP | E33: Web / IAP | F33: Web / IAP | G33: Web / IAP | H33: Web | I33: Web | J33: IAP | K33: IAP | L33: IAP | M33: IAP | N33: Web | O33: Web | P33: Web | Q33: =+IFERROR(VLOOKUP(B33,[2]Apple!$B$3:$C$173,2,FALSE),"") | R33: =+IFERROR(VLOOKUP(B33,[2]Google!$B$3:$C$99,2,FALSE),"")
B34: Brazil | C34: =+VLOOKUP($B34,'[2]Pricing Scenario - Maintain'!$B$4:$AM$238,2,FALSE) -> Latin America | D34: Web & IAP | E34: Web & IAP | F34: Web & IAP | G34: Web & IAP | H34: Web | I34: Web | J34: IAP | K34: IAP | L34: IAP | M34: IAP | N34: Web | O34: Web | P34: Web | Q34: =+IFERROR(VLOOKUP(B34,[2]Apple!$B$3:$C$173,2,FALSE),"") -> BR | R34: =+IFERROR(VLOOKUP(B34,[2]Google!$B$3:$C$99,2,FALSE),"") -> BR
B35: British Indian Ocean Territory | C35: =+VLOOKUP($B35,'[2]Pricing Scenario - Maintain'!$B$4:$AM$238,2,FALSE) -> Asia | D35: Web / IAP | E35: Web / IAP | F35: Web / IAP | G35: Web / IAP | H35: Web | I35: Web | J35: IAP | K35: IAP | L35: IAP | M35: IAP | N35: Web | O35: Web | P35: Web | Q35: =+IFERROR(VLOOKUP(B35,[2]Apple!$B$3:$C$173,2,FALSE),"") | R35: =+IFERROR(VLOOKUP(B35,[2]Google!$B$3:$C$99,2,FALSE),"")
B36: British Virgin Islands | C36: =+VLOOKUP($B36,'[2]Pricing Scenario - Maintain'!$B$4:$AM$238,2,FALSE) -> Latin America | D36: Web & IAP | E36: Web & IAP | F36: Web & IAP | G36: Web & IAP | H36: Web | I36: Web | J36: IAP | K36: IAP | L36: IAP | M36: IAP | N36: Web | O36: Web | P36: Web | Q36: =+IFERROR(VLOOKUP(B36,[2]Apple!$B$3:$C$173,2,FALSE),"") -> VG | R36: =+IFERROR(VLOOKUP(B36,[2]Google!$B$3:$C$99,2,FALSE),"") -> VG
B37: Brunei | C37: =+VLOOKUP($B37,'[2]Pricing Scenario - Maintain'!$B$4:$AM$238,2,FALSE) -> Asia | D37: Web & IAP | E37: Web & IAP | F37: Web & IAP | G37: Web & IAP | H37: Web | I37: Web | J37: IAP | K37: IAP | L37: IAP | M37: IAP | N37: Web | O37: Web | P37: Web | Q37: =+IFERROR(VLOOKUP(B37,[2]Apple!$B$3:$C$173,2,FALSE),"") -> BN | R37: =+IFERROR(VLOOKUP(B37,[2]Google!$B$3:$C$99,2,FALSE),"")
B38: Bulgaria | C38: =+VLOOKUP($B38,'[2]Pricing Scenario - Maintain'!$B$4:$AM$238,2,FALSE) -> Europe | D38: Web & IAP | E38: Web & IAP | F38: Web & IAP | G38: Web & IAP | H38: Web | I38: Web | J38: IAP | K38: IAP | L38: IAP | M38: IAP | N38: Web | O38: Web | P38: Web | Q38: =+IFERROR(VLOOKUP(B38,[2]Apple!$B$3:$C$173,2,FALSE),"") -> BG | R38: =+IFERROR(VLOOKUP(B38,[2]Google!$B$3:$C$99,2,FALSE),"") -> BG
B39: Burkina Faso | C39: =+VLOOKUP($B39,'[2]Pricing Scenario - Maintain'!$B$4:$AM$238,2,FALSE) -> Africa | D39: Web & IAP | E39: Web & IAP | F39: Web & IAP | G39: Web & IAP | H39: Web | I39: Web | J39: IAP | K39: IAP | L39: IAP | M39: IAP | N39: Web | O39: Web | P39: Web | Q39: =+IFERROR(VLOOKUP(B39,[2]Apple!$B$3:$C$173,2,FALSE),"") -> BF | R39: =+IFERROR(VLOOKUP(B39,[2]Google!$B$3:$C$99,2,FALSE),"") -> BF
B40: Burundi | C40: =+VLOOKUP($B40,'[2]Pricing Scenario - Maintain'!$B$4:$AM$238,2,FALSE) -> Africa | D40: Web / IAP | E40: Web / IAP | F40: Web / IAP | G40: Web / IAP | H40: Web | I40: Web | J40: IAP | K40: IAP | L40: IAP | M40: IAP | N40: Web | O40: Web | P40: Web | Q40: =+IFERROR(VLOOKUP(B40,[2]Apple!$B$3:$C$173,2,FALSE),"") | R40: =+IFERROR(VLOOKUP(B40,[2]Google!$B$3:$C$99,2,FALSE),"")
B41: Cambodia | C41: =+VLOOKUP($B41,'[2]Pricing Scenario - Maintain'!$B$4:$AM$238,2,FALSE) -> Asia | D41: Web & IAP | E41: Web & IAP | F41: Web & IAP | G41: Web & IAP | H41: Web | I41: Web | J41: IAP | K41: IAP | L41: IAP | M41: IAP | N41: Web | O41: Web | P41: Web | Q41: =+IFERROR(VLOOKUP(B41,[2]Apple!$B$3:$C$173,2,FALSE),"") -> KH | R41: =+IFERROR(VLOOKUP(B41,[2]Google!$B$3:$C$99,2,FALSE),"") -> KH
B42: Cameroon | C42: =+VLOOKUP($B42,'[2]Pricing Scenario - Maintain'!$B$4:$AM$238,2,FALSE) -> Africa | D42: Web & IAP | E42: Web & IAP | F42: Web & IAP | G42: Web & IAP | H42: Web | I42: Web | J42: IAP | K42: IAP | L42: IAP | M42: IAP | N42: Web | O42: Web | P42: Web | Q42: =+IFERROR(VLOOKUP(B42,[2]Apple!$B$3:$C$173,2,FALSE),"") -> CM | R42: =+IFERROR(VLOOKUP(B42,[2]Google!$B$3:$C$99,2,FALSE),"") -> CM
... B78: France | C78: =+VLOOKUP($B78,'[2]Pricing Scenario - Maintain'!$B$4:$AM$238,2,FALSE) -> Europe | D78: Web & IAP | E78: Web & IAP | F78: Web & IAP | G78: Web & IAP | H78: Web | I78: Web | J78: IAP | K78: IAP | L78: IAP | M78: IAP | N78: Web | O78: Web | P78: Web | Q78: =+IFERROR(VLOOKUP(B78,[2]Apple!$B$3:$C$173,2,FALSE),"") -> FR | R78: =+IFERROR(VLOOKUP(B78,[2]Google!$B$3:$C$99,2,FALSE),"") -> FR
B79: French Guiana | C79: Europe | D79: Web / IAP | E79: Web / IAP | F79: Web / IAP | G79: Web / IAP | H79: Web | I79: Web | J79: IAP | K79: IAP | L79: IAP | M79: IAP | N79: Web | O79: Web | P79: Web | Q79: =+IFERROR(VLOOKUP(B79,[2]Apple!$B$3:$C$173,2,FALSE),"") | R79: =+IFERROR(VLOOKUP(B79,[2]Google!$B$3:$C$99,2,FALSE),"")
B80: French Polynesia | C80: =+VLOOKUP($B80,'[2]Pricing Scenario - Maintain'!$B$4:$AM$238,2,FALSE) -> Asia | D80: Web / IAP | E80: Web / IAP | F80: Web / IAP | G80: Web / IAP | H80: Web | I80: Web | J80: IAP | K80: IAP | L80: IAP | M80: IAP | N80: Web | O80: Web | P80: Web | Q80: =+IFERROR(VLOOKUP(B80,[2]Apple!$B$3:$C$173,2,FALSE),"") | R80: =+IFERROR(VLOOKUP(B80,[2]Google!$B$3:$C$99,2,FALSE),"")
B81: French Southern Territories | C81: =+VLOOKUP($B81,'[2]Pricing Scenario - Maintain'!$B$4:$AM$238,2,FALSE) -> Europe | D81: Web / IAP | E81: Web / IAP | F81: Web / IAP | G81: Web / IAP | H81: Web | I81: Web | J81: IAP | K81: IAP | L81: IAP | M81: IAP | N81: Web | O81: Web | P81: Web | Q81: =+IFERROR(VLOOKUP(B81,[2]Apple!$B$3:$C$173,2,FALSE),"") | R81: =+IFERROR(VLOOKUP(B81,[2]Google!$B$3:$C$99,2,FALSE),"")
B82: Gabon | C82: =+VLOOKUP($B82,'[2]Pricing Scenario - Maintain'!$B$4:$AM$238,2,FALSE) -> Africa | D82: Web & IAP | E82: Web & IAP | F82: Web & IAP | G82: Web & IAP | H82: Web | I82: Web | J82: IAP | K82: IAP | L82: IAP | M82: IAP | N82: Web | O82: Web | P82: Web | Q82: =+IFERROR(VLOOKUP(B82,[2]Apple!$B$3:$C$173,2,FALSE),"") -> GA | R82: =+IFERROR(VLOOKUP(B82,[2]Google!$B$3:$C$99,2,FALSE),"") -> GA
B83: Gambia | C83: =+VLOOKUP($B83,'[2]Pricing Scenario - Maintain'!$B$4:$AM$238,2,FALSE) -> Africa | D83: Web & IAP | E83: Web & IAP | F83: Web & IAP | G83: Web & IAP | H83: Web | I83: Web | J83: IAP | K83: IAP | L83: IAP | M83: IAP | N83: Web | O83: Web | P83: Web | Q83: =+IFERROR(VLOOKUP(B83,[2]Apple!$B$3:$C$173,2,FALSE),"") -> GM | R83: =+IFERROR(VLOOKUP(B83,[2]Google!$B$3:$C$99,2,FALSE),"") -> GM
...

Sheet Pricing by Platform ->

Sheet DOM Web
B2: Country | C2: Region | D2: BLPEUSTV | E2: BLPEUSTVMONTHLY | F2: BLPPUSTV | G2: BLPPUSSTVMONTHLY | H2: BTCUS | I2: BTCUSMONTHLY | J2: BLPTV | K2: BLPTVMONTHLY | L2: BLPAUDIO
B3: United States | C3: Domestic | D3: 159.99 | E3: 24.99 | F3: 109.99 | G3: 16.99 | H3: 89.99 | I3: 13.99 | J3: 74.99 | K3: 8.99 | L3: 9.99
B4: Guam | C4: Domestic | D4: =+D$3 -> 159.99 | E4: =+E$3 -> 24.99 | F4: =+F$3 -> 109.99 | G4: =+G$3 -> 16.99 | H4: =+H$3 -> 89.99 | I4: =+I$3 -> 13.99 | J4: =+J$3 -> 74.99 | K4: =+K$3 -> 8.99 | L4: =+L$3 -> 9.99
B5: Puerto Rico | C5: Domestic | D5: =+D$3 -> 159.99 | E5: =+E$3 -> 24.99 | F5: =+F$3 -> 109.99 | G5: =+G$3 -> 16.99 | H5: =+H$3 -> 89.99 | I5: =+I$3 -> 13.99 | J5: =+J$3 -> 74.99 | K5: =+K$3 -> 8.99 | L5: =+L$3 -> 9.99
B6: US Virgin Islands | C6: Domestic | D6: =+D$3 -> 159.99 | E6: =+E$3 -> 24.99 | F6: =+F$3 -> 109.99 | G6: =+G$3 -> 16.99 | H6: =+H$3 -> 89.99 | I6: =+I$3 -> 13.99 | J6: =+J$3 -> 74.99 | K6: =+K$3 -> 8.99 | L6: =+L$3 -> 9.99
B7: US Minor Outlying Islands | C7: Domestic | D7: =+D$3 -> 159.99 | E7: =+E$3 -> 24.99 | F7: =+F$3 -> 109.99 | G7: =+G$3 -> 16.99 | H7: =+H$3 -> 89.99 | I7: =+I$3 -> 13.99 | J7: =+J$3 -> 74.99 | K7: =+K$3 -> 8.99 | L7: =+L$3 -> 9.99

Sheet INT Web
B1: 1 | C1: =+B1+1 -> 2 | D1: =+C1+1 -> 3 | E1: =+D1+1 -> 4 | F1: =+E1+1 -> 5 | G1: =+F1+1 -> 6 | H1: =+G1+1 -> 7 | I1: =+H1+1 -> 8 | J1: =+I1+1 -> 9 | ... AQ1: =+AP1+1 -> 42
R2: BLPE | S2: BLPEMONTHLY | T2: BLPP | U2: BLPPMONTHLY | V2: BTC | W2: BTCMONTHLY | AK2: 46209 | AL2: BLPE | AM2: BLPEMONTHLY | AN2: BLPP | AO2: BLPPMONTHLY | AP2: BTC | AQ2: BTCMONTHLY
D3: Old Priority Mkt | E3: FY26 Start of Season Pricing (in Local Currency) | L3: FY26 Start of Season Sub. Length and SKU Ratios | Q3: FY27 Start of Season Pricing (in Local Currency) | X3: FY27 Start of Season Sub. Length and SKU Ratios | AD3: YoY FY27 vs. FY26 Start of Season Pricing | AK3: FY27 Start of Season Pricing (in USD)
B4: Country | C4: Region | D4: Segment | E4: Currency | F4: LPP Annual | G4: LPP Monthly | H4: LP Annual | I4: LP Monthly | J4: TC Annual | K4: TC Monthly | L4: LPP SubL. | M4: LPP SKU | N4: LP SubL. | O4: TP SubL. | P4: TP SKU | Q4: Currency | R4: LPP Annual | S4: LPP Monthly | T4: LP Annual | U4: LP Monthly | V4: TC Annual | W4: TC Monthly | X4: LPP SubL. | Y4: LPP SKU | Z4: LP SubL. | AA4: TP SubL. | AB4: TP SKU | AD4: LPP Annual | AE4: LPP Monthly | AF4: LP Annual | AG4: LP Monthly | AH4: TC Annual | AI4: TC Monthly | AK4: FX to USD | AL4: LPP Annual | AM4: LPP Monthly | AN4: LP Annual | AO4: LP Monthly | AP4: TC Annual | AQ4: TC Monthly | AS4: Two Digit Country Code
B5: Afghanistan | C5: Asia | E5: =+VLOOKUP($B5,'[3]INT Web'!$B$5:$W$247,'[3]INT Web'!Q$1,FALSE) -> USD | F5: =+VLOOKUP($B5,'[3]INT Web'!$B$5:$W$247,'[3]INT Web'!R$1,FALSE) -> 71.99 | G5: =+VLOOKUP($B5,'[3]INT Web'!$B$5:$W$247,'[3]INT Web'!S$1,FALSE) -> 11.99 | H5: =+VLOOKUP($B5,'[3]INT Web'!$B$5:$W$247,'[3]INT Web'!T$1,FALSE) -> 53.99 | I5: =+VLOOKUP($B5,'[3]INT Web'!$B$5:$W$247,'[3]INT Web'!U$1,FALSE) -> 8.99 | J5: =+VLOOKUP($B5,'[3]INT Web'!$B$5:$W$247,'[3]INT Web'!V$1,FALSE) -> 47.99 | K5: =+VLOOKUP($B5,'[3]INT Web'!$B$5:$W$247,'[3]INT Web'!W$1,FALSE) -> 7.99 | L5: =+F5/G5 -> 6.0041701 | M5: =+G5/I5 -> 1.3337041 | N5: =+H5/I5 -> 6.0055617 | O5: =+J5/K5 -> 6.0062578 | P5: =+K5/I5 -> 0.88876529 | Q5: =+E5 -> USD | R5: =+VLOOKUP($B5,'Country-Level Tactics'!$B$5:$AL$248,'Country-Level Tactics'!AH$1,FALSE) -> 71.99 | S5: =+VLOOKUP($B5,'Country-Level Tactics'!$B$5:$AL$248,'Country-Level Tactics'!X$1,FALSE) -> 11.99 | T5: =+VLOOKUP($B5,'Country-Level Tactics'!$B$5:$AL$248,'Country-Level Tactics'!AC$1,FALSE) -> 53.99 | U5: =+VLOOKUP($B5,'Country-Level Tactics'!$B$5:$AL$248,'Country-Level Tactics'!T$1,FALSE) -> 8.99 | V5: =+J5 -> 47.99 | W5: =+K5 -> 7.99 | X5: =+R5/S5 -> 6.0041701 | Y5: =+S5/U5 -> 1.3337041 | Z5: =+T5/U5 -> 6.0055617 | AA5: =+V5/W5 -> 6.0062578 | AB5: =+W5/U5 -> 0.88876529 | AD5: =+R5/F5-1 -> 0 | AE5: =+S5/G5-1 -> 0 | AF5: =+T5/H5-1 -> 0 | AG5: =+U5/I5-1 -> 0 | AH5: =+V5/J5-1 -> 0 | AI5: =+W5/K5-1 -> 0 | AK5: {=_xll.FDS("","P_EXCH_RATE("&Q5&",USD,"&$AK$2&")")} -> 1 | AL5: =+R5*$AK5 -> 71.99 | AM5: =+S5*$AK5 -> 11.99 | AN5: =+T5*$AK5 -> 53.99 | AO5: =+U5*$AK5 -> 8.99 | AP5: =+V5*$AK5 -> 47.99 | AQ5: =+W5*$AK5 -> 7.99 | AS5: =+VLOOKUP(B5,'Country & Code Abbreviation'!$B$3:$C$245,2,FALSE) -> AF
B6: Aland Islands | C6: Europe | E6: =+VLOOKUP($B6,'[3]INT Web'!$B$5:$W$247,'[3]INT Web'!Q$1,FALSE) -> EUR | F6: =+VLOOKUP($B6,'[3]INT Web'!$B$5:$W$247,'[3]INT Web'!R$1,FALSE) -> 119.99 | G6: =+VLOOKUP($B6,'[3]INT Web'!$B$5:$W$247,'[3]INT Web'!S$1,FALSE) -> 19.99 | H6: =+VLOOKUP($B6,'[3]INT Web'!$B$5:$W$247,'[3]INT Web'!T$1,FALSE) -> 89.99 | I6: =+VLOOKUP($B6,'[3]INT Web'!$B$5:$W$247,'[3]INT Web'!U$1,FALSE) -> 14.99 | J6: =+VLOOKUP($B6,'[3]INT Web'!$B$5:$W$247,'[3]INT Web'!V$1,FALSE) -> 79.99 | K6: =+VLOOKUP($B6,'[3]INT Web'!$B$5:$W$247,'[3]INT Web'!W$1,FALSE) -> 12.99 | L6: =+F6/G6 -> 6.0025013 | M6: =+G6/I6 -> 1.3335557 | N6: =+H6/I6 -> 6.0033356 | O6: =+J6/K6 -> 6.1578137 | P6: =+K6/I6 -> 0.86657772 | Q6: =+E6 -> EUR | R6: =+VLOOKUP($B6,'Country-Level Tactics'!$B$5:$AL$248,'Country-Level Tactics'!AH$1,FALSE) -> 119.99 | S6: =+VLOOKUP($B6,'Country-Level Tactics'!$B$5:$AL$248,'Country-Level Tactics'!X$1,FALSE) -> 19.99 | T6: =+VLOOKUP($B6,'Country-Level Tactics'!$B$5:$AL$248,'Country-Level Tactics'!AC$1,FALSE) -> 89.99 | U6: =+VLOOKUP($B6,'Country-Level Tactics'!$B$5:$AL$248,'Country-Level Tactics'!T$1,FALSE) -> 14.99 | V6: =+J6 -> 79.99 | W6: =+K6 -> 12.99 | X6: =+R6/S6 -> 6.0025013 | Y6: =+S6/U6 -> 1.3335557 | Z6: =+T6/U6 -> 6.0033356 | AA6: =+V6/W6 -> 6.1578137 | AB6: =+W6/U6 -> 0.86657772 | AD6: =+R6/F6-1 -> 0 | AE6: =+S6/G6-1 -> 0 | AF6: =+T6/H6-1 -> 0 | AG6: =+U6/I6-1 -> 0 | AH6: =+V6/J6-1 -> 0 | AI6: =+W6/K6-1 -> 0 | AK6: {=_xll.FDS("","P_EXCH_RATE("&Q6&",USD,"&$AK$2&")")} -> 1.14175 | AL6: =+R6*$AK6 -> 136.99858 | AM6: =+S6*$AK6 -> 22.823583 | AN6: =+T6*$AK6 -> 102.74608 | AO6: =+U6*$AK6 -> 17.114833 | AP6: =+V6*$AK6 -> 91.328582 | AQ6: =+W6*$AK6 -> 14.831333 | AS6: =+VLOOKUP(B6,'Country & Code Abbreviation'!$B$3:$C$245,2,FALSE) -> AX
B7: Albania | C7: Europe | E7: =+VLOOKUP($B7,'[3]INT Web'!$B$5:$W$247,'[3]INT Web'!Q$1,FALSE) -> ALL | F7: =+VLOOKUP($B7,'[3]INT Web'!$B$5:$W$247,'[3]INT Web'!R$1,FALSE) -> 9719.99 | G7: =+VLOOKUP($B7,'[3]INT Web'!$B$5:$W$247,'[3]INT Web'!S$1,FALSE) -> 1619.99 | H7: =+VLOOKUP($B7,'[3]INT Web'!$B$5:$W$247,'[3]INT Web'!T$1,FALSE) -> 7199.99 | I7: =+VLOOKUP($B7,'[3]INT Web'!$B$5:$W$247,'[3]INT Web'!U$1,FALSE) -> 1199.99 | J7: =+VLOOKUP($B7,'[3]INT Web'!$B$5:$W$247,'[3]INT Web'!V$1,FALSE) -> 6479.99 | K7: =+VLOOKUP($B7,'[3]INT Web'!$B$5:$W$247,'[3]INT Web'!W$1,FALSE) -> 1079.99 | L7: =+F7/G7 -> 6.0000309 | M7: =+G7/I7 -> 1.3500029 | N7: =+H7/I7 -> 6.0000417 | O7: =+J7/K7 -> 6.0000463 | P7: =+K7/I7 -> 0.89999917 | Q7: =+E7 -> ALL | R7: =+VLOOKUP($B7,'Country-Level Tactics'!$B$5:$AL$248,'Country-Level Tactics'!AH$1,FALSE) -> 9719.99 | S7: =+VLOOKUP($B7,'Country-Level Tactics'!$B$5:$AL$248,'Country-Level Tactics'!X$1,FALSE) -> 1619.99 | T7: =+VLOOKUP($B7,'Country-Level Tactics'!$B$5:$AL$248,'Country-Level Tactics'!AC$1,FALSE) -> 7199.99 | U7: =+VLOOKUP($B7,'Country-Level Tactics'!$B$5:$AL$248,'Country-Level Tactics'!T$1,FALSE) -> 1199.99 | V7: =+J7 -> 6479.99 | W7: =+K7 -> 1079.99 | X7: =+R7/S7 -> 6.0000309 | Y7: =+S7/U7 -> 1.3500029 | Z7: =+T7/U7 -> 6.0000417 | AA7: =+V7/W7 -> 6.0000463 | AB7: =+W7/U7 -> 0.89999917 | AD7: =+R7/F7-1 -> 0 | AE7: =+S7/G7-1 -> 0 | AF7: =+T7/H7-1 -> 0 | AG7: =+U7/I7-1 -> 0 | AH7: =+V7/J7-1 -> 0 | AI7: =+W7/K7-1 -> 0 | AK7: {=_xll.FDS("","P_EXCH_RATE("&Q7&",USD,"&$AK$2&")")} -> 0.012172114 | AL7: =+R7*$AK7 -> 118.31283 | AM7: =+S7*$AK7 -> 19.718703 | AN7: =+T7*$AK7 -> 87.639099 | AO7: =+U7*$AK7 -> 14.606415 | AP7: =+V7*$AK7 -> 78.875177 | AQ7: =+W7*$AK7 -> 13.145761 | AS7: =+VLOOKUP(B7,'Country & Code Abbreviation'!$B$3:$C$245,2,FALSE) -> AL
B8: Algeria | C8: Africa | E8: =+VLOOKUP($B8,'[3]INT Web'!$B$5:$W$247,'[3]INT Web'!Q$1,FALSE) -> DZD | F8: =+VLOOKUP($B8,'[3]INT Web'!$B$5:$W$247,'[3]INT Web'!R$1,FALSE) -> 8099.99 | G8: =+VLOOKUP($B8,'[3]INT Web'!$B$5:$W$247,'[3]INT Web'!S$1,FALSE) -> 1349.99 | H8: =+VLOOKUP($B8,'[3]INT Web'!$B$5:$W$247,'[3]INT Web'!T$1,FALSE) -> 5999.99 | I8: =+VLOOKUP($B8,'[3]INT Web'!$B$5:$W$247,'[3]INT Web'!U$1,FALSE) -> 999.99 | J8: =+VLOOKUP($B8,'[3]INT Web'!$B$5:$W$247,'[3]INT Web'!V$1,FALSE) -> 5399.99 | K8: =+VLOOKUP($B8,'[3]INT Web'!$B$5:$W$247,'[3]INT Web'!W$1,FALSE) -> 899.99 | L8: =+F8/G8 -> 6.000037 | M8: =+G8/I8 -> 1.3500035 | N8: =+H8/I8 -> 6.00005 | O8: =+J8/K8 -> 6.0000556 | P8: =+K8/I8 -> 0.899999 | Q8: =+E8 -> DZD | R8: =+VLOOKUP($B8,'Country-Level Tactics'!$B$5:$AL$248,'Country-Level Tactics'!AH$1,FALSE) -> 8099.99 | S8: =+VLOOKUP($B8,'Country-Level Tactics'!$B$5:$AL$248,'Country-Level Tactics'!X$1,FALSE) -> 1349.99 | T8: =+VLOOKUP($B8,'Country-Level Tactics'!$B$5:$AL$248,'Country-Level Tactics'!AC$1,FALSE) -> 5999.99 | U8: =+VLOOKUP($B8,'Country-Level Tactics'!$B$5:$AL$248,'Country-Level Tactics'!T$1,FALSE) -> 999.99 | V8: =+J8 -> 5399.99 | W8: =+K8 -> 899.99 | X8: =+R8/S8 -> 6.000037 | Y8: =+S8/U8 -> 1.3500035 | Z8: =+T8/U8 -> 6.00005 | AA8: =+V8/W8 -> 6.0000556 | AB8: =+W8/U8 -> 0.899999 | AD8: =+R8/F8-1 -> 0 | AE8: =+S8/G8-1 -> 0 | AF8: =+T8/H8-1 -> 0 | AG8: =+U8/I8-1 -> 0 | AH8: =+V8/J8-1 -> 0 | AI8: =+W8/K8-1 -> 0 | AK8: {=_xll.FDS("","P_EXCH_RATE("&Q8&",USD,"&$AK$2&")")} -> 0.007511675 | AL8: =+R8*$AK8 -> 60.844492 | AM8: =+S8*$AK8 -> 10.140686 | AN8: =+T8*$AK8 -> 45.069975 | AO8: =+U8*$AK8 -> 7.5115999 | AP8: =+V8*$AK8 -> 40.56297 | AQ8: =+W8*$AK8 -> 6.7604324 | AS8: =+VLOOKUP(B8,'Country & Code Abbreviation'!$B$3:$C$245,2,FALSE) -> DZ
B9: American Samoa | C9: Asia | E9: =+VLOOKUP($B9,'[3]INT Web'!$B$5:$W$247,'[3]INT Web'!Q$1,FALSE) -> USD | F9: =+VLOOKUP($B9,'[3]INT Web'!$B$5:$W$247,'[3]INT Web'!R$1,FALSE) -> 129.99 | G9: =+VLOOKUP($B9,'[3]INT Web'!$B$5:$W$247,'[3]INT Web'!S$1,FALSE) -> 18.99 | H9: =+VLOOKUP($B9,'[3]INT Web'!$B$5:$W$247,'[3]INT Web'!T$1,FALSE) -> 83.99 | I9: =+VLOOKUP($B9,'[3]INT Web'!$B$5:$W$247,'[3]INT Web'!U$1,FALSE) -> 13.99 | J9: =+VLOOKUP($B9,'[3]INT Web'!$B$5:$W$247,'[3]INT Web'!V$1,FALSE) -> 77.99 | K9: =+VLOOKUP($B9,'[3]INT Web'!$B$5:$W$247,'[3]INT Web'!W$1,FALSE) -> 12.99 | L9: =+F9/G9 -> 6.8451817 | M9: =+G9/I9 -> 1.3573981 | N9: =+H9/I9 -> 6.003574 | O9: =+J9/K9 -> 6.0038491 | P9: =+K9/I9 -> 0.92852037 | Q9: =+E9 -> USD | R9: =+VLOOKUP($B9,'Country-Level Tactics'!$B$5:$AL$248,'Country-Level Tactics'!AH$1,FALSE) -> 129.99 | S9: =+VLOOKUP($B9,'Country-Level Tactics'!$B$5:$AL$248,'Country-Level Tactics'!X$1,FALSE) -> 18.99 | T9: =+VLOOKUP($B9,'Country-Level Tactics'!$B$5:$AL$248,'Country-Level Tactics'!AC$1,FALSE) -> 83.99 | U9: =+VLOOKUP($B9,'Country-Level Tactics'!$B$5:$AL$248,'Country-Level Tactics'!T$1,FALSE) -> 13.99 | V9: =+J9 -> 77.99 | W9: =+K9 -> 12.99 | X9: =+R9/S9 -> 6.8451817 | Y9: =+S9/U9 -> 1.3573981 | Z9: =+T9/U9 -> 6.003574 | AA9: =+V9/W9 -> 6.0038491 | AB9: =+W9/U9 -> 0.92852037 | AD9: =+R9/F9-1 -> 0 | AE9: =+S9/G9-1 -> 0 | AF9: =+T9/H9-1 -> 0 | AG9: =+U9/I9-1 -> 0 | AH9: =+V9/J9-1 -> 0 | AI9: =+W9/K9-1 -> 0 | AK9: {=_xll.FDS("","P_EXCH_RATE("&Q9&",USD,"&$AK$2&")")} -> 1 | AL9: =+R9*$AK9 -> 129.99 | AM9: =+S9*$AK9 -> 18.99 | AN9: =+T9*$AK9 -> 83.99 | AO9: =+U9*$AK9 -> 13.99 | AP9: =+V9*$AK9 -> 77.99 | AQ9: =+W9*$AK9 -> 12.99 | AS9: =+VLOOKUP(B9,'Country & Code Abbreviation'!$B$3:$C$245,2,FALSE) -> AS
B10: Andorra | C10: Europe | E10: =+VLOOKUP($B10,'[3]INT Web'!$B$5:$W$247,'[3]INT Web'!Q$1,FALSE) -> EUR | F10: =+VLOOKUP($B10,'[3]INT Web'!$B$5:$W$247,'[3]INT Web'!R$1,FALSE) -> 159.99 | G10: =+VLOOKUP($B10,'[3]INT Web'!$B$5:$W$247,'[3]INT Web'!S$1,FALSE) -> 22.99 | H10: =+VLOOKUP($B10,'[3]INT Web'!$B$5:$W$247,'[3]INT Web'!T$1,FALSE) -> 109.99 | I10: =+VLOOKUP($B10,'[3]INT Web'!$B$5:$W$247,'[3]INT Web'!U$1,FALSE) -> 17.99 | J10: =+VLOOKUP($B10,'[3]INT Web'!$B$5:$W$247,'[3]INT Web'!V$1,FALSE) -> 99.99 | K10: =+VLOOKUP($B10,'[3]INT Web'!$B$5:$W$247,'[3]INT Web'!W$1,FALSE) -> 15.99 | L10: =+F10/G10 -> 6.9591127 | M10: =+G10/I10 -> 1.2779322 | N10: =+H10/I10 -> 6.1139522 | O10: =+J10/K10 -> 6.2532833 | P10: =+K10/I10 -> 0.88882713 | Q10: =+E10 -> EUR | R10: =+VLOOKUP($B10,'Country-Level Tactics'!$B$5:$AL$248,'Country-Level Tactics'!AH$1,FALSE) -> 159.99 | S10: =+VLOOKUP($B10,'Country-Level Tactics'!$B$5:$AL$248,'Country-Level Tactics'!X$1,FALSE) -> 22.99 | T10: =+VLOOKUP($B10,'Country-Level Tactics'!$B$5:$AL$248,'Country-Level Tactics'!AC$1,FALSE) -> 109.99 | U10: =+VLOOKUP($B10,'Country-Level Tactics'!$B$5:$AL$248,'Country-Level Tactics'!T$1,FALSE) -> 17.99 | V10: =+J10 -> 99.99 | W10: =+K10 -> 15.99 | X10: =+R10/S10 -> 6.9591127 | Y10: =+S10/U10 -> 1.2779322 | Z10: =+T10/U10 -> 6.1139522 | AA10: =+V10/W10 -> 6.2532833 | AB10: =+W10/U10 -> 0.88882713 | AD10: =+R10/F10-1 -> 0 | AE10: =+S10/G10-1 -> 0 | AF10: =+T10/H10-1 -> 0 | AG10: =+U10/I10-1 -> 0 | AH10: =+V10/J10-1 -> 0 | AI10: =+W10/K10-1 -> 0 | AK10: {=_xll.FDS("","P_EXCH_RATE("&Q10&",USD,"&$AK$2&")")} -> 1.14175 | AL10: =+R10*$AK10 -> 182.66858 | AM10: =+S10*$AK10 -> 26.248832 | AN10: =+T10*$AK10 -> 125.58108 | AO10: =+U10*$AK10 -> 20.540083 | AP10: =+V10*$AK10 -> 114.16358 | AQ10: =+W10*$AK10 -> 18.256583 | AS10: =+VLOOKUP(B10,'Country & Code Abbreviation'!$B$3:$C$245,2,FALSE) -> AD
B11: Angola | C11: Africa | E11: =+VLOOKUP($B11,'[3]INT Web'!$B$5:$W$247,'[3]INT Web'!Q$1,FALSE) -> USD | F11: =+VLOOKUP($B11,'[3]INT Web'!$B$5:$W$247,'[3]INT Web'!R$1,FALSE) -> 71.99 | G11: =+VLOOKUP($B11,'[3]INT Web'!$B$5:$W$247,'[3]INT Web'!S$1,FALSE) -> 11.99 | H11: =+VLOOKUP($B11,'[3]INT Web'!$B$5:$W$247,'[3]INT Web'!T$1,FALSE) -> 53.99 | I11: =+VLOOKUP($B11,'[3]INT Web'!$B$5:$W$247,'[3]INT Web'!U$1,FALSE) -> 8.99 | J11: =+VLOOKUP($B11,'[3]INT Web'!$B$5:$W$247,'[3]INT Web'!V$1,FALSE) -> 47.99 | K11: =+VLOOKUP($B11,'[3]INT Web'!$B$5:$W$247,'[3]INT Web'!W$1,FALSE) -> 7.99 | L11: =+F11/G11 -> 6.0041701 | M11: =+G11/I11 -> 1.3337041 | N11: =+H11/I11 -> 6.0055617 | O11: =+J11/K11 -> 6.0062578 | P11: =+K11/I11 -> 0.88876529 | Q11: =+E11 -> USD | R11: =+VLOOKUP($B11,'Country-Level Tactics'!$B$5:$AL$248,'Country-Level Tactics'!AH$1,FALSE) -> 71.99 | S11: =+VLOOKUP($B11,'Country-Level Tactics'!$B$5:$AL$248,'Country-Level Tactics'!X$1,FALSE) -> 11.99 | T11: =+VLOOKUP($B11,'Country-Level Tactics'!$B$5:$AL$248,'Country-Level Tactics'!AC$1,FALSE) -> 53.99 | U11: =+VLOOKUP($B11,'Country-Level Tactics'!$B$5:$AL$248,'Country-Level Tactics'!T$1,FALSE) -> 8.99 | V11: =+J11 -> 47.99 | W11: =+K11 -> 7.99 | X11: =+R11/S11 -> 6.0041701 | Y11: =+S11/U11 -> 1.3337041 | Z11: =+T11/U11 -> 6.0055617 | AA11: =+V11/W11 -> 6.0062578 | AB11: =+W11/U11 -> 0.88876529 | AD11: =+R11/F11-1 -> 0 | AE11: =+S11/G11-1 -> 0 | AF11: =+T11/H11-1 -> 0 | AG11: =+U11/I11-1 -> 0 | AH11: =+V11/J11-1 -> 0 | AI11: =+W11/K11-1 -> 0 | AK11: {=_xll.FDS("","P_EXCH_RATE("&Q11&",USD,"&$AK$2&")")} -> 1 | AL11: =+R11*$AK11 -> 71.99 | AM11: =+S11*$AK11 -> 11.99 | AN11: =+T11*$AK11 -> 53.99 | AO11: =+U11*$AK11 -> 8.99 | AP11: =+V11*$AK11 -> 47.99 | AQ11: =+W11*$AK11 -> 7.99 | AS11: =+VLOOKUP(B11,'Country & Code Abbreviation'!$B$3:$C$245,2,FALSE) -> AO
B12: Anguilla | C12: Latin America | E12: =+VLOOKUP($B12,'[3]INT Web'!$B$5:$W$247,'[3]INT Web'!Q$1,FALSE) -> XCD | F12: =+VLOOKUP($B12,'[3]INT Web'!$B$5:$W$247,'[3]INT Web'!R$1,FALSE) -> 269.99 | G12: =+VLOOKUP($B12,'[3]INT Web'!$B$5:$W$247,'[3]INT Web'!S$1,FALSE) -> 44.99 | H12: =+VLOOKUP($B12,'[3]INT Web'!$B$5:$W$247,'[3]INT Web'!T$1,FALSE) -> 197.99 | I12: =+VLOOKUP($B12,'[3]INT Web'!$B$5:$W$247,'[3]INT Web'!U$1,FALSE) -> 32.99 | J12: =+VLOOKUP($B12,'[3]INT Web'!$B$5:$W$247,'[3]INT Web'!V$1,FALSE) -> 179.99 | K12: =+VLOOKUP($B12,'[3]INT Web'!$B$5:$W$247,'[3]INT Web'!W$1,FALSE) -> 29.99 | L12: =+F12/G12 -> 6.0011114 | M12: =+G12/I12 -> 1.3637466 | N12: =+H12/I12 -> 6.0015156 | O12: =+J12/K12 -> 6.0016672 | P12: =+K12/I12 -> 0.90906335 | Q12: =+E12 -> XCD | R12: =+VLOOKUP($B12,'Country-Level Tactics'!$B$5:$AL$248,'Country-Level Tactics'!AH$1,FALSE) -> 269.99 | S12: =+VLOOKUP($B12,'Country-Level Tactics'!$B$5:$AL$248,'Country-Level Tactics'!X$1,FALSE) -> 44.99 | T12: =+VLOOKUP($B12,'Country-Level Tactics'!$B$5:$AL$248,'Country-Level Tactics'!AC$1,FALSE) -> 197.99 | U12: =+VLOOKUP($B12,'Country-Level Tactics'!$B$5:$AL$248,'Country-Level Tactics'!T$1,FALSE) -> 32.99 | V12: =+J12 -> 179.99 | W12: =+K12 -> 29.99 | X12: =+R12/S12 -> 6.0011114 | Y12: =+S12/U12 -> 1.3637466 | Z12: =+T12/U12 -> 6.0015156 | AA12: =+V12/W12 -> 6.0016672 | AB12: =+W12/U12 -> 0.90906335 | AD12: =+R12/F12-1 -> 0 | AE12: =+S12/G12-1 -> 0 | AF12: =+T12/H12-1 -> 0 | AG12: =+U12/I12-1 -> 0 | AH12: =+V12/J12-1 -> 0 | AI12: =+W12/K12-1 -> 0 | AK12: {=_xll.FDS("","P_EXCH_RATE("&Q12&",USD,"&$AK$2&")")} -> 0.37037036 | AL12: =+R12*$AK12 -> 99.996293 | AM12: =+S12*$AK12 -> 16.662962 | AN12: =+T12*$AK12 -> 73.329628 | AO12: =+U12*$AK12 -> 12.218518 | AP12: =+V12*$AK12 -> 66.662961 | AQ12: =+W12*$AK12 -> 11.107407 | AS12: =+VLOOKUP(B12,'Country & Code Abbreviation'!$B$3:$C$245,2,FALSE) -> AI
B13: Antarctica | C13: Europe | E13: =+VLOOKUP($B13,'[3]INT Web'!$B$5:$W$247,'[3]INT Web'!Q$1,FALSE) -> USD | F13: =+VLOOKUP($B13,'[3]INT Web'!$B$5:$W$247,'[3]INT Web'!R$1,FALSE) -> 154.99 | G13: =+VLOOKUP($B13,'[3]INT Web'!$B$5:$W$247,'[3]INT Web'!S$1,FALSE) -> 21.99 | H13: =+VLOOKUP($B13,'[3]INT Web'!$B$5:$W$247,'[3]INT Web'!T$1,FALSE) -> 99.99 | I13: =+VLOOKUP($B13,'[3]INT Web'!$B$5:$W$247,'[3]INT Web'!U$1,FALSE) -> 16.99 | J13: =+VLOOKUP($B13,'[3]INT Web'!$B$5:$W$247,'[3]INT Web'!V$1,FALSE) -> 89.99 | K13: =+VLOOKUP($B13,'[3]INT Web'!$B$5:$W$247,'[3]INT Web'!W$1,FALSE) -> 14.99 | L13: =+F13/G13 -> 7.0482037 | M13: =+G13/I13 -> 1.2942908 | N13: =+H13/I13 -> 5.8852266 | O13: =+J13/K13 -> 6.0033356 | P13: =+K13/I13 -> 0.8822837 | Q13: =+E13 -> USD | R13: =+VLOOKUP($B13,'Country-Level Tactics'!$B$5:$AL$248,'Country-Level Tactics'!AH$1,FALSE) -> 154.99 | S13: =+VLOOKUP($B13,'Country-Level Tactics'!$B$5:$AL$248,'Country-Level Tactics'!X$1,FALSE) -> 21.99 | T13: =+VLOOKUP($B13,'Country-Level Tactics'!$B$5:$AL$248,'Country-Level Tactics'!AC$1,FALSE) -> 99.99 | U13: =+VLOOKUP($B13,'Country-Level Tactics'!$B$5:$AL$248,'Country-Level Tactics'!T$1,FALSE) -> 16.99 | V13: =+J13 -> 89.99 | W13: =+K13 -> 14.99 | X13: =+R13/S13 -> 7.0482037 | Y13: =+S13/U13 -> 1.2942908 | Z13: =+T13/U13 -> 5.8852266 | AA13: =+V13/W13 -> 6.0033356 | AB13: =+W13/U13 -> 0.8822837 | AD13: =+R13/F13-1 -> 0 | AE13: =+S13/G13-1 -> 0 | AF13: =+T13/H13-1 -> 0 | AG13: =+U13/I13-1 -> 0 | AH13: =+V13/J13-1 -> 0 | AI13: =+W13/K13-1 -> 0 | AK13: {=_xll.FDS("","P_EXCH_RATE("&Q13&",USD,"&$AK$2&")")} -> 1 | AL13: =+R13*$AK13 -> 154.99 | AM13: =+S13*$AK13 -> 21.99 | AN13: =+T13*$AK13 -> 99.99 | AO13: =+U13*$AK13 -> 16.99 | AP13: =+V13*$AK13 -> 89.99 | AQ13: =+W13*$AK13 -> 14.99 | AS13: =+VLOOKUP(B13,'Country & Code Abbreviation'!$B$3:$C$245,2,FALSE) -> AQ
B14: Antigua And Barbuda | C14: Latin America | E14: =+VLOOKUP($B14,'[3]INT Web'!$B$5:$W$247,'[3]INT Web'!Q$1,FALSE) -> XCD | F14: =+VLOOKUP($B14,'[3]INT Web'!$B$5:$W$247,'[3]INT Web'!R$1,FALSE) -> 305.99 | G14: =+VLOOKUP($B14,'[3]INT Web'!$B$5:$W$247,'[3]INT Web'!S$1,FALSE) -> 50.99 | H14: =+VLOOKUP($B14,'[3]INT Web'!$B$5:$W$247,'[3]INT Web'!T$1,FALSE) -> 227.99 | I14: =+VLOOKUP($B14,'[3]INT Web'!$B$5:$W$247,'[3]INT Web'!U$1,FALSE) -> 37.99 | J14: =+VLOOKUP($B14,'[3]INT Web'!$B$5:$W$247,'[3]INT Web'!V$1,FALSE) -> 203.99 | K14: =+VLOOKUP($B14,'[3]INT Web'!$B$5:$W$247,'[3]INT Web'!W$1,FALSE) -> 33.99 | L14: =+F14/G14 -> 6.0009806 | M14: =+G14/I14 -> 1.3421953 | N14: =+H14/I14 -> 6.0013161 | O14: =+J14/K14 -> 6.001471 | P14: =+K14/I14 -> 0.89470913 | Q14: =+E14 -> XCD | R14: =+VLOOKUP($B14,'Country-Level Tactics'!$B$5:$AL$248,'Country-Level Tactics'!AH$1,FALSE) -> 305.99 | S14: =+VLOOKUP($B14,'Country-Level Tactics'!$B$5:$AL$248,'Country-Level Tactics'!X$1,FALSE) -> 50.99 | T14: =+VLOOKUP($B14,'Country-Level Tactics'!$B$5:$AL$248,'Country-Level Tactics'!AC$1,FALSE) -> 227.99 | U14: =+VLOOKUP($B14,'Country-Level Tactics'!$B$5:$AL$248,'Country-Level Tactics'!T$1,FALSE) -> 37.99 | V14: =+J14 -> 203.99 | W14: =+K14 -> 33.99 | X14: =+R14/S14 -> 6.0009806 | Y14: =+S14/U14 -> 1.3421953 | Z14: =+T14/U14 -> 6.0013161 | AA14: =+V14/W14 -> 6.001471 | AB14: =+W14/U14 -> 0.89470913 | AD14: =+R14/F14-1 -> 0 | AE14: =+S14/G14-1 -> 0 | AF14: =+T14/H14-1 -> 0 | AG14: =+U14/I14-1 -> 0 | AH14: =+V14/J14-1 -> 0 | AI14: =+W14/K14-1 -> 0 | AK14: {=_xll.FDS("","P_EXCH_RATE("&Q14&",USD,"&$AK$2&")")} -> 0.37037036 | AL14: =+R14*$AK14 -> 113.32963 | AM14: =+S14*$AK14 -> 18.885185 | AN14: =+T14*$AK14 -> 84.440738 | AO14: =+U14*$AK14 -> 14.07037 | AP14: =+V14*$AK14 -> 75.55185 | AQ14: =+W14*$AK14 -> 12.588889 | AS14: =+VLOOKUP(B14,'Country & Code Abbreviation'!$B$3:$C$245,2,FALSE) -> AG
B15: Argentina | C15: Latin America | D15: C | E15: =+VLOOKUP($B15,'[3]INT Web'!$B$5:$W$247,'[3]INT Web'!Q$1,FALSE) -> ARS | F15: =+VLOOKUP($B15,'[3]INT Web'!$B$5:$W$247,'[3]INT Web'!R$1,FALSE) -> 206519.99 | G15: =+VLOOKUP($B15,'[3]INT Web'!$B$5:$W$247,'[3]INT Web'!S$1,FALSE) -> 34419.99 | H15: =+VLOOKUP($B15,'[3]INT Web'!$B$5:$W$247,'[3]INT Web'!T$1,FALSE) -> 163899.99 | I15: =+VLOOKUP($B15,'[3]INT Web'!$B$5:$W$247,'[3]INT Web'!U$1,FALSE) -> 26819.985 | J15: =+VLOOKUP($B15,'[3]INT Web'!$B$5:$W$247,'[3]INT Web'!V$1,FALSE) -> 145279.99 | K15: =+VLOOKUP($B15,'[3]INT Web'!$B$5:$W$247,'[3]INT Web'!W$1,FALSE) -> 23839.985 | L15: =+F15/G15 -> 6.0000015 | M15: =+G15/I15 -> 1.283371 | N15: =+H15/I15 -> 6.111114 | O15: =+J15/K15 -> 6.0939631 | P15: =+K15/I15 -> 0.88888883 | Q15: USD | R15: =+VLOOKUP($B15,'Country-Level Tactics'!$B$5:$AL$248,'Country-Level Tactics'!AH$1,FALSE) -> 79.99 | S15: =+VLOOKUP($B15,'Country-Level Tactics'!$B$5:$AL$248,'Country-Level Tactics'!X$1,FALSE) -> 12.99 | T15: =+VLOOKUP($B15,'Country-Level Tactics'!$B$5:$AL$248,'Country-Level Tactics'!AC$1,FALSE) -> 59.99 | U15: =+VLOOKUP($B15,'Country-Level Tactics'!$B$5:$AL$248,'Country-Level Tactics'!T$1,FALSE) -> 9.99 | V15: =+MROUND(T15*P15,1)-0.01 -> 52.99 | W15: =+MROUND(U15*P15,1)-0.01 -> 8.99 | X15: =+R15/S15 -> 6.1578137 | Y15: =+S15/U15 -> 1.3003003 | Z15: =+T15/U15 -> 6.005005 | AA15: =+V15/W15 -> 5.894327 | AB15: =+W15/U15 -> 0.8998999 | AD15: =+R15/F15-1 -> -0.99961268 | AE15: =+S15/G15-1 -> -0.9996226 | AF15: =+T15/H15-1 -> -0.99963398 | AG15: =+U15/I15-1 -> -0.99962752 | AH15: =+V15/J15-1 -> -0.99963526 | AI15: =+W15/K15-1 -> -0.9996229 | AK15: {=_xll.FDS("","P_EXCH_RATE("&Q15&",USD,"&$AK$2&")")} -> 1 | AL15: =+R15*$AK15 -> 79.99 | AM15: =+S15*$AK15 -> 12.99 | AN15: =+T15*$AK15 -> 59.99 | AO15: =+U15*$AK15 -> 9.99 | AP15: =+V15*$AK15 -> 52.99 | AQ15: =+W15*$AK15 -> 8.99 | AS15: =+VLOOKUP(B15,'Country & Code Abbreviation'!$B$3:$C$245,2,FALSE) -> AR
B16: Armenia | C16: Middle East | E16: =+VLOOKUP($B16,'[3]INT Web'!$B$5:$W$247,'[3]INT Web'!Q$1,FALSE) -> AMD | F16: =+VLOOKUP($B16,'[3]INT Web'!$B$5:$W$247,'[3]INT Web'!R$1,FALSE) -> 54269.99 | G16: =+VLOOKUP($B16,'[3]INT Web'!$B$5:$W$247,'[3]INT Web'!S$1,FALSE) -> 9039.99 | H16: =+VLOOKUP($B16,'[3]INT Web'!$B$5:$W$247,'[3]INT Web'!T$1,FALSE) -> 40199.99 | I16: =+VLOOKUP($B16,'[3]INT Web'!$B$5:$W$247,'[3]INT Web'!U$1,FALSE) -> 6699.99 | J16: =+VLOOKUP($B16,'[3]INT Web'!$B$5:$W$247,'[3]INT Web'!V$1,FALSE) -> 36179.99 | K16: =+VLOOKUP($B16,'[3]INT Web'!$B$5:$W$247,'[3]INT Web'!W$1,FALSE) -> 6029.99 | L16: =+F16/G16 -> 6.0033241 | M16: =+G16/I16 -> 1.3492543 | N16: =+H16/I16 -> 6.0000075 | O16: =+J16/K16 -> 6.0000083 | P16: =+K16/I16 -> 0.89999985 | Q16: =+E16 -> AMD | R16: =+VLOOKUP($B16,'Country-Level Tactics'!$B$5:$AL$248,'Country-Level Tactics'!AH$1,FALSE) -> 54269.99 | S16: =+VLOOKUP($B16,'Country-Level Tactics'!$B$5:$AL$248,'Country-Level Tactics'!X$1,FALSE) -> 9039.99 | T16: =+VLOOKUP($B16,'Country-Level Tactics'!$B$5:$AL$248,'Country-Level Tactics'!AC$1,FALSE) -> 40199.99 | U16: =+VLOOKUP($B16,'Country-Level Tactics'!$B$5:$AL$248,'Country-Level Tactics'!T$1,FALSE) -> 6699.99 | V16: =+J16 -> 36179.99 | W16: =+K16 -> 6029.99 | X16: =+R16/S16 -> 6.0033241 | Y16: =+S16/U16 -> 1.3492543 | Z16: =+T16/U16 -> 6.0000075 | AA16: =+V16/W16 -> 6.0000083 | AB16: =+W16/U16 -> 0.89999985 | AD16: =+R16/F16-1 -> 0 | AE16: =+S16/G16-1 -> 0 | AF16: =+T16/H16-1 -> 0 | AG16: =+U16/I16-1 -> 0 | AH16: =+V16/J16-1 -> 0 | AI16: =+W16/K16-1 -> 0 | AK16: {=_xll.FDS("","P_EXCH_RATE("&Q16&",USD,"&$AK$2&")")} -> 0.0027159413 | AL16: =+R16*$AK16 -> 147.39411 | AM16: =+S16*$AK16 -> 24.552082 | AN16: =+T16*$AK16 -> 109.18081 | AO16: =+U16*$AK16 -> 18.19678 | AP16: =+V16*$AK16 -> 98.262729 | AQ16: =+W15*$AK16 -> 0.024416312 | AS16: =+VLOOKUP(B16,'Country & Code Abbreviation'!$B$3:$C$245,2,FALSE) -> AM
B17: Aruba | C17: Latin America | E17: =+VLOOKUP($B17,'[3]INT Web'!$B$5:$W$247,'[3]INT Web'!Q$1,FALSE) -> AWG | F17: =+VLOOKUP($B17,'[3]INT Web'!$B$5:$W$247,'[3]INT Web'!R$1,FALSE) -> 179.99 | G17: =+VLOOKUP($B17,'[3]INT Web'!$B$5:$W$247,'[3]INT Web'!S$1,FALSE) -> 29.99 | H17: =+VLOOKUP($B17,'[3]INT Web'!$B$5:$W$247,'[3]INT Web'!T$1,FALSE) -> 131.99 | I17: =+VLOOKUP($B17,'[3]INT Web'!$B$5:$W$247,'[3]INT Web'!U$1,FALSE) -> 21.99 | J17: =+VLOOKUP($B17,'[3]INT Web'!$B$5:$W$247,'[3]INT Web'!V$1,FALSE) -> 119.99 | K17: =+VLOOKUP($B17,'[3]INT Web'!$B$5:$W$247,'[3]INT Web'!W$1,FALSE) -> 19.99 | L17: =+F17/G17 -> 6.0016672 | M17: =+G17/I17 -> 1.3638017 | N17: =+H17/I17 -> 6.0022738 | O17: =+J17/K17 -> 6.0025013 | P17: =+K17/I17 -> 0.90904957 | Q17: =+E17 -> AWG | R17: =+VLOOKUP($B17,'Country-Level Tactics'!$B$5:$AL$248,'Country-Level Tactics'!AH$1,FALSE) -> 179.99 | S17: =+VLOOKUP($B17,'Country-Level Tactics'!$B$5:$AL$248,'Country-Level Tactics'!X$1,FALSE) -> 29.99 | T17: =+VLOOKUP($B17,'Country-Level Tactics'!$B$5:$AL$248,'Country-Level Tactics'!AC$1,FALSE) -> 131.99 | U17: =+VLOOKUP($B17,'Country-Level Tactics'!$B$5:$AL$248,'Country-Level Tactics'!T$1,FALSE) -> 21.99 | V17: =+J17 -> 119.99 | W17: =+K17 -> 19.99 | X17: =+R17/S17 -> 6.0016672 | Y17: =+S17/U17 -> 1.3638017 | Z17: =+T17/U17 -> 6.0022738 | AA17: =+V17/W17 -> 6.0025013 | AB17: =+W17/U17 -> 0.90904957 | AD17: =+R17/F17-1 -> 0 | AE17: =+S17/G17-1 -> 0 | AF17: =+T17/H17-1 -> 0 | AG17: =+U17/I17-1 -> 0 | AH17: =+V17/J17-1 -> 0 | AI17: =+W17/K17-1 -> 0 | AK17: {=_xll.FDS("","P_EXCH_RATE("&Q17&",USD,"&$AK$2&")")} -> 0.55865926 | AL17: =+R17*$AK17 -> 100.55308 | AM17: =+S17*$AK17 -> 16.754191 | AN17: =+T17*$AK17 -> 73.737436 | AO17: =+U17*$AK17 -> 12.284917 | AP17: =+V17*$AK17 -> 67.033525 | AQ17: =+W17*$AK17 -> 11.167599 | AS17: =+VLOOKUP(B17,'Country & Code Abbreviation'!$B$3:$C$245,2,FALSE) -> AW
B18: Australia | C18: Asia | D18: B | E18: =+VLOOKUP($B18,'[3]INT Web'!$B$5:$W$247,'[3]INT Web'!Q$1,FALSE) -> AUD | F18: =+VLOOKUP($B18,'[3]INT Web'!$B$5:$W$247,'[3]INT Web'!R$1,FALSE) -> 229.99 | G18: =+VLOOKUP($B18,'[3]INT Web'!$B$5:$W$247,'[3]INT Web'!S$1,FALSE) -> 32.99 | H18: =+VLOOKUP($B18,'[3]INT Web'!$B$5:$W$247,'[3]INT Web'!T$1,FALSE) -> 174.99 | I18: =+VLOOKUP($B18,'[3]INT Web'!$B$5:$W$247,'[3]INT Web'!U$1,FALSE) -> 24.99 | J18: =+VLOOKUP($B18,'[3]INT Web'!$B$5:$W$247,'[3]INT Web'!V$1,FALSE) -> 153.99 | K18: =+VLOOKUP($B18,'[3]INT Web'!$B$5:$W$247,'[3]INT Web'!W$1,FALSE) -> 21.99 | L18: =+F18/G18 -> 6.9715065 | M18: =+G18/I18 -> 1.3201281 | N18: =+H18/I18 -> 7.002401 | O18: =+J18/K18 -> 7.0027285 | P18: =+K18/I18 -> 0.87995198 | Q18: =+E18 -> AUD | R18: =+VLOOKUP($B18,'Country-Level Tactics'!$B$5:$AL$248,'Country-Level Tactics'!AH$1,FALSE) -> 244.99 | S18: =+VLOOKUP($B18,'Country-Level Tactics'!$B$5:$AL$248,'Country-Level Tactics'!X$1,FALSE) -> 34.99 | T18: =+VLOOKUP($B18,'Country-Level Tactics'!$B$5:$AL$248,'Country-Level Tactics'!AC$1,FALSE) -> 174.99 | U18: =+VLOOKUP($B18,'Country-Level Tactics'!$B$5:$AL$248,'Country-Level Tactics'!T$1,FALSE) -> 24.99 | V18: =+J18 -> 153.99 | W18: =+K18 -> 21.99 | X18: =+R18/S18 -> 7.0017148 | Y18: =+S18/U18 -> 1.4001601 | Z18: =+T18/U18 -> 7.002401 | AA18: =+V18/W18 -> 7.0027285 | AB18: =+W18/U18 -> 0.87995198 | AD18: =+R18/F18-1 -> 0.065220227 | AE18: =+S18/G18-1 -> 0.060624432 | AF18: =+T18/H18-1 -> 0 | AG18: =+U18/I18-1 -> 0 | AH18: =+V18/J18-1 -> 0 | AI18: =+W18/K18-1 -> 0 | AK18: {=_xll.FDS("","P_EXCH_RATE("&Q18&",USD,"&$AK$2&")")} -> 0.69375 | AL18: =+R18*$AK18 -> 169.96181 | AM18: =+S18*$AK18 -> 24.274313 | AN18: =+T18*$AK18 -> 121.39931 | AO18: =+U18*$AK18 -> 17.336812 | AP18: =+V18*$AK18 -> 106.83056 | AQ18: =+W18*$AK18 -> 15.255562 | AS18: =+VLOOKUP(B18,'Country & Code Abbreviation'!$B$3:$C$245,2,FALSE) -> AU
B19: Austria | C19: Europe | E19: =+VLOOKUP($B19,'[3]INT Web'!$B$5:$W$247,'[3]INT Web'!Q$1,FALSE) -> EUR | F19: =+VLOOKUP($B19,'[3]INT Web'!$B$5:$W$247,'[3]INT Web'!R$1,FALSE) -> 159.99 | G19: =+VLOOKUP($B19,'[3]INT Web'!$B$5:$W$247,'[3]INT Web'!S$1,FALSE) -> 23.99 | H19: =+VLOOKUP($B19,'[3]INT Web'!$B$5:$W$247,'[3]INT Web'!T$1,FALSE) -> 116.99 | I19: =+VLOOKUP($B19,'[3]INT Web'!$B$5:$W$247,'[3]INT Web'!U$1,FALSE) -> 17.99 | J19: =+VLOOKUP($B19,'[3]INT Web'!$B$5:$W$247,'[3]INT Web'!V$1,FALSE) -> 104.99 | K19: =+VLOOKUP($B19,'[3]INT Web'!$B$5:$W$247,'[3]INT Web'!W$1,FALSE) -> 15.99 | L19: =+F19/G19 -> 6.6690288 | M19: =+G19/I19 -> 1.3335186 | N19: =+H19/I19 -> 6.5030573 | O19: =+J19/K19 -> 6.5659787 | P19: =+K19/I19 -> 0.88882713 | Q19: =+E19 -> EUR | R19: =+VLOOKUP($B19,'Country-Level Tactics'!$B$5:$AL$248,'Country-Level Tactics'!AH$1,FALSE) -> 159.99 | S19: =+VLOOKUP($B19,'Country-Level Tactics'!$B$5:$AL$248,'Country-Level Tactics'!X$1,FALSE) -> 23.99 | T19: =+VLOOKUP($B19,'Country-Level Tactics'!$B$5:$AL$248,'Country-Level Tactics'!AC$1,FALSE) -> 116.99 | U19: =+VLOOKUP($B19,'Country-Level Tactics'!$B$5:$AL$248,'Country-Level Tactics'!T$1,FALSE) -> 17.99 | V19: =+J19 -> 104.99 | W19: =+K19 -> 15.99 | X19: =+R19/S19 -> 6.6690288 | Y19: =+S19/U19 -> 1.3335186 | Z19: =+T19/U19 -> 6.5030573 | AA19: =+V19/W19 -> 6.5659787 | AB19: =+W19/U19 -> 0.88882713 | AD19: =+R19/F19-1 -> 0 | AE19: =+S19/G19-1 -> 0 | AF19: =+T19/H19-1 -> 0 | AG19: =+U19/I19-1 -> 0 | AH19: =+V19/J19-1 -> 0 | AI19: =+W19/K19-1 -> 0 | AK19: {=_xll.FDS("","P_EXCH_RATE("&Q19&",USD,"&$AK$2&")")} -> 1.14175 | AL19: =+R19*$AK19 -> 182.66858 | AM19: =+S19*$AK19 -> 27.390583 | AN19: =+T19*$AK19 -> 133.57333 | AO19: =+U19*$AK19 -> 20.540083 | AP19: =+V19*$AK19 -> 119.87233 | AQ19: =+W19*$AK19 -> 18.256583 | AS19: =+VLOOKUP(B19,'Country & Code Abbreviation'!$B$3:$C$245,2,FALSE) -> AT
B20: Azerbaijan | C20: Middle East | E20: =+VLOOKUP($B20,'[3]INT Web'!$B$5:$W$247,'[3]INT Web'!Q$1,FALSE) -> AZN | F20: =+VLOOKUP($B20,'[3]INT Web'!$B$5:$W$247,'[3]INT Web'!R$1,FALSE) -> 179.99 | G20: =+VLOOKUP($B20,'[3]INT Web'!$B$5:$W$247,'[3]INT Web'!S$1,FALSE) -> 29.99 | H20: =+VLOOKUP($B20,'[3]INT Web'!$B$5:$W$247,'[3]INT Web'!T$1,FALSE) -> 129.99 | I20: =+VLOOKUP($B20,'[3]INT Web'!$B$5:$W$247,'[3]INT Web'!U$1,FALSE) -> 21.99 | J20: =+VLOOKUP($B20,'[3]INT Web'!$B$5:$W$247,'[3]INT Web'!V$1,FALSE) -> 119.99 | K20: =+VLOOKUP($B20,'[3]INT Web'!$B$5:$W$247,'[3]INT Web'!W$1,FALSE) -> 19.99 | L20: =+F20/G20 -> 6.0016672 | M20: =+G20/I20 -> 1.3638017 | N20: =+H20/I20 -> 5.9113233 | O20: =+J20/K20 -> 6.0025013 | P20: =+K20/I20 -> 0.90904957 | Q20: =+E20 -> AZN | R20: =+VLOOKUP($B20,'Country-Level Tactics'!$B$5:$AL$248,'Country-Level Tactics'!AH$1,FALSE) -> 179.99 | S20: =+VLOOKUP($B20,'Country-Level Tactics'!$B$5:$AL$248,'Country-Level Tactics'!X$1,FALSE) -> 29.99 | T20: =+VLOOKUP($B20,'Country-Level Tactics'!$B$5:$AL$248,'Country-Level Tactics'!AC$1,FALSE) -> 129.99 | U20: =+VLOOKUP($B20,'Country-Level Tactics'!$B$5:$AL$248,'Country-Level Tactics'!T$1,FALSE) -> 21.99 | V20: =+J20 -> 119.99 | W20: =+K20 -> 19.99 | X20: =+R20/S20 -> 6.0016672 | Y20: =+S20/U20 -> 1.3638017 | Z20: =+T20/U20 -> 5.9113233 | AA20: =+V20/W20 -> 6.0025013 | AB20: =+W20/U20 -> 0.90904957 | AD20: =+R20/F20-1 -> 0 | AE20: =+S20/G20-1 -> 0 | AF20: =+T20/H20-1 -> 0 | AG20: =+U20/I20-1 -> 0 | AH20: =+V20/J20-1 -> 0 | AI20: =+W20/K20-1 -> 0 | AK20: {=_xll.FDS("","P_EXCH_RATE("&Q20&",USD,"&$AK$2&")")} -> 0.58823526 | AL20: =+R20*$AK20 -> 105.87646 | AM20: =+S20*$AK20 -> 17.641175 | AN20: =+T20*$AK20 -> 76.464701 | AO20: =+U20*$AK20 -> 12.935293 | AP20: =+V20*$AK20 -> 70.582349 | AQ20: =+W20*$AK20 -> 11.758823 | AS20: =+VLOOKUP(B20,'Country & Code Abbreviation'!$B$3:$C$245,2,FALSE) -> AZ
B21: Bahamas | C21: Latin America | E21: =+VLOOKUP($B21,'[3]INT Web'!$B$5:$W$247,'[3]INT Web'!Q$1,FALSE) -> BSD | F21: =+VLOOKUP($B21,'[3]INT Web'!$B$5:$W$247,'[3]INT Web'!R$1,FALSE) -> 95.99 | G21: =+VLOOKUP($B21,'[3]INT Web'!$B$5:$W$247,'[3]INT Web'!S$1,FALSE) -> 15.99 | H21: =+VLOOKUP($B21,'[3]INT Web'!$B$5:$W$247,'[3]INT Web'!T$1,FALSE) -> 71.99 | I21: =+VLOOKUP($B21,'[3]INT Web'!$B$5:$W$247,'[3]INT Web'!U$1,FALSE) -> 11.99 | J21: =+VLOOKUP($B21,'[3]INT Web'!$B$5:$W$247,'[3]INT Web'!V$1,FALSE) -> 65.99 | K21: =+VLOOKUP($B21,'[3]INT Web'!$B$5:$W$247,'[3]INT Web'!W$1,FALSE) -> 10.99 | L21: =+F21/G21 -> 6.003127 | M21: =+G21/I21 -> 1.3336113 | N21: =+H21/I21 -> 6.0041701 | O21: =+J21/K21 -> 6.0045496 | P21: =+K21/I21 -> 0.91659716 | Q21: =+E21 -> BSD | R21: =+VLOOKUP($B21,'Country-Level Tactics'!$B$5:$AL$248,'Country-Level Tactics'!AH$1,FALSE) -> 95.99 | S21: =+VLOOKUP($B21,'Country-Level Tactics'!$B$5:$AL$248,'Country-Level Tactics'!X$1,FALSE) -> 15.99 | T21: =+VLOOKUP($B21,'Country-Level Tactics'!$B$5:$AL$248,'Country-Level Tactics'!AC$1,FALSE) -> 71.99 | U21: =+VLOOKUP($B21,'Country-Level Tactics'!$B$5:$AL$248,'Country-Level Tactics'!T$1,FALSE) -> 11.99 | V21: =+J21 -> 65.99 | W21: =+K21 -> 10.99 | X21: =+R21/S21 -> 6.003127 | Y21: =+S21/U21 -> 1.3336113 | Z21: =+T21/U21 -> 6.0041701 | AA21: =+V21/W21 -> 6.0045496 | AB21: =+W21/U21 -> 0.91659716 | AD21: =+R21/F21-1 -> 0 | AE21: =+S21/G21-1 -> 0 | AF21: =+T21/H21-1 -> 0 | AG21: =+U21/I21-1 -> 0 | AH21: =+V21/J21-1 -> 0 | AI21: =+W21/K21-1 -> 0 | AK21: {=_xll.FDS("","P_EXCH_RATE("&Q21&",USD,"&$AK$2&")")} -> 1 | AL21: =+R21*$AK21 -> 95.99 | AM21: =+S21*$AK21 -> 15.99 | AN21: =+T21*$AK21 -> 71.99 | AO21: =+U21*$AK21 -> 11.99 | AP21: =+V21*$AK21 -> 65.99 | AQ21: =+W21*$AK21 -> 10.99 | AS21: =+VLOOKUP(B21,'Country & Code Abbreviation'!$B$3:$C$245,2,FALSE) -> BS
B22: Bahrain | C22: Middle East | E22: =+VLOOKUP($B22,'[3]INT Web'!$B$5:$W$247,'[3]INT Web'!Q$1,FALSE) -> BHD | F22: =+VLOOKUP($B22,'[3]INT Web'!$B$5:$W$247,'[3]INT Web'!R$1,FALSE) -> 59.999 | G22: =+VLOOKUP($B22,'[3]INT Web'!$B$5:$W$247,'[3]INT Web'!S$1,FALSE) -> 8.999 | H22: =+VLOOKUP($B22,'[3]INT Web'!$B$5:$W$247,'[3]INT Web'!T$1,FALSE) -> 49.999 | I22: =+VLOOKUP($B22,'[3]INT Web'!$B$5:$W$247,'[3]INT Web'!U$1,FALSE) -> 6.999 | J22: =+VLOOKUP($B22,'[3]INT Web'!$B$5:$W$247,'[3]INT Web'!V$1,FALSE) -> 39.999 | K22: =+VLOOKUP($B22,'[3]INT Web'!$B$5:$W$247,'[3]INT Web'!W$1,FALSE) -> 5.999 | L22: =+F22/G22 -> 6.6672964 | M22: =+G22/I22 -> 1.2857551 | N22: =+H22/I22 -> 7.1437348 | O22: =+J22/K22 -> 6.6676113 | P22: =+K22/I22 -> 0.85712245 | Q22: =+E22 -> BHD | R22: =+VLOOKUP($B22,'Country-Level Tactics'!$B$5:$AL$248,'Country-Level Tactics'!AH$1,FALSE) -> 59.999 | S22: =+VLOOKUP($B22,'Country-Level Tactics'!$B$5:$AL$248,'Country-Level Tactics'!X$1,FALSE) -> 8.999 | T22: =+VLOOKUP($B22,'Country-Level Tactics'!$B$5:$AL$248,'Country-Level Tactics'!AC$1,FALSE) -> 49.999 | U22: =+VLOOKUP($B22,'Country-Level Tactics'!$B$5:$AL$248,'Country-Level Tactics'!T$1,FALSE) -> 6.999 | V22: =+J22 -> 39.999 | W22: =+K22 -> 5.999 | X22: =+R22/S22 -> 6.6672964 | Y22: =+S22/U22 -> 1.2857551 | Z22: =+T22/U22 -> 7.1437348 | AA22: =+V22/W22 -> 6.6676113 | AB22: =+W22/U22 -> 0.85712245 | AD22: =+R22/F22-1 -> 0 | AE22: =+S22/G22-1 -> 0 | AF22: =+T22/H22-1 -> 0 | AG22: =+U22/I22-1 -> 0 | AH22: =+V22/J22-1 -> 0 | AI22: =+W22/K22-1 -> 0 | AK22: {=_xll.FDS("","P_EXCH_RATE("&Q22&",USD,"&$AK$2&")")} -> 2.65252 | AL22: =+R22*$AK22 -> 159.14855 | AM22: =+S22*$AK22 -> 23.870027 | AN22: =+T22*$AK22 -> 132.62335 | AO22: =+U22*$AK22 -> 18.564987 | AP22: =+V22*$AK22 -> 106.09815 | AQ22: =+W22*$AK22 -> 15.912467 | AS22: =+VLOOKUP(B22,'Country & Code Abbreviation'!$B$3:$C$245,2,FALSE) -> BH
B23: Bangladesh | C23: Asia | E23: =+VLOOKUP($B23,'[3]INT Web'!$B$5:$W$247,'[3]INT Web'!Q$1,FALSE) -> BDT | F23: =+VLOOKUP($B23,'[3]INT Web'!$B$5:$W$247,'[3]INT Web'!R$1,FALSE) -> 6071.99 | G23: =+VLOOKUP($B23,'[3]INT Web'!$B$5:$W$247,'[3]INT Web'!S$1,FALSE) -> 1011.99 | H23: =+VLOOKUP($B23,'[3]INT Web'!$B$5:$W$247,'[3]INT Web'!T$1,FALSE) -> 4499.99 | I23: =+VLOOKUP($B23,'[3]INT Web'!$B$5:$W$247,'[3]INT Web'!U$1,FALSE) -> 749.99 | J23: =+VLOOKUP($B23,'[3]INT Web'!$B$5:$W$247,'[3]INT Web'!V$1,FALSE) -> 4049.99 | K23: =+VLOOKUP($B23,'[3]INT Web'!$B$5:$W$247,'[3]INT Web'!W$1,FALSE) -> 674.99 | L23: =+F23/G23 -> 6.0000494 | M23: =+G23/I23 -> 1.349338 | N23: =+H23/I23 -> 6.0000667 | O23: =+J23/K23 -> 6.0000741 | P23: =+K23/I23 -> 0.89999867 | Q23: =+E23 -> BDT | R23: =+VLOOKUP($B23,'Country-Level Tactics'!$B$5:$AL$248,'Country-Level Tactics'!AH$1,FALSE) -> 6071.99 | S23: =+VLOOKUP($B23,'Country-Level Tactics'!$B$5:$AL$248,'Country-Level Tactics'!X$1,FALSE) -> 1011.99 | T23: =+VLOOKUP($B23,'Country-Level Tactics'!$B$5:$AL$248,'Country-Level Tactics'!AC$1,FALSE) -> 4499.99 | U23: =+VLOOKUP($B23,'Country-Level Tactics'!$B$5:$AL$248,'Country-Level Tactics'!T$1,FALSE) -> 749.99 | V23: =+J23 -> 4049.99 | W23: =+K23 -> 674.99 | X23: =+R23/S23 -> 6.0000494 | Y23: =+S23/U23 -> 1.349338 | Z23: =+T23/U23 -> 6.0000667 | AA23: =+V23/W23 -> 6.0000741 | AB23: =+W23/U23 -> 0.89999867 | AD23: =+R23/F23-1 -> 0 | AE23: =+S23/G23-1 -> 0 | AF23: =+T23/H23-1 -> 0 | AG23: =+U23/I23-1 -> 0 | AH23: =+V23/J23-1 -> 0 | AI23: =+W23/K23-1 -> 0 | AK23: 0.00811359 | AL23: =+R23*$AK23 -> 49.265637 | AM23: =+S23*$AK23 -> 8.2108719 | AN23: =+T23*$AK23 -> 36.511074 | AO23: =+U23*$AK23 -> 6.0851114 | AP23: =+V23*$AK23 -> 32.859958 | AQ23: =+W23*$AK23 -> 5.4765921 | AS23: =+VLOOKUP(B23,'Country & Code Abbreviation'!$B$3:$C$245,2,FALSE) -> BD
